Workbook
Name \c: #REF!
Name \P: #REF!
Name \PX: #REF!
Name \s: #REF!
Name ___rr1: #REF!
Name __rr1: #REF!
Name Admin2020: #REF!
Name Admin2020: #REF!
Name AdminBgt2020: #REF!
Name AP: #REF!
Name APAGE: #REF!
Name APAGEX: #REF!
Name BCLASS2022: #REF!
Name BCLASS2022: #REF!
Name BLKPAGE: #REF!
Name BLKPAGEX: #REF!
Name BPAGE: #REF!
Name BPAGEX: #REF!
Name BUDGET_Title: #REF!
Name BUSINESSCLASS: #REF!
Name BUSINESSCLASS: #REF!
Name By: #REF!
Name C_: #REF!
Name C_X: #REF!
Name Client: #REF!
Name ColumnTitle1: #REF!
Name COMPANY_NAME: #REF!
Name CON: #REF!
Name Concentration: #REF!
Name CONX: #REF!
Name CPAGE: #REF!
Name CPAGEX: #REF!
Name CurDate: #REF!
Name CurRev: #REF!
Name CurrRev: #REF!
Name Date: #REF!
Name Datenum: #REF!
Name DateRev: #REF!
Name DOC: #REF!
Name DocNo: #REF!
Name Docnum: #REF!
Name Document: #REF!
Name DOMJNRPERDIEM: #REF!
Name DOMJNRPERDIEM: #REF!
Name DOMSNRPERDIEM: #REF!
Name DOMSNRPERDIEM: #REF!
Name DONRPERDIEM2022: #REF!
Name DONRPERDIEM2022: #REF!
Name DOPERDIEM2022: #REF!
Name DOPERDIEM2022: #REF!
Name DPAGE: #REF!
Name DsNo: #REF!
Name DYE: #REF!
Name ECONOMYCL2022: #REF!
Name ECONOMYCL2022: #REF!
Name ECONOMYCLASS: #REF!
Name ECONOMYCLASS: #REF!
Name EPAGE: #REF!
Name EQP: #REF!
Name Essai: #REF!

Sheet SALES BUDGET
C3: GOBITUMEN LIMITED
B4: REVENUE BUDGET FOR THE YEAR 2026
G7: Scenario | H7: Worst case
C10: FY 2025 ANALYSIS | G10: 2026 REVENUE BUDGET
B11: in '000 | C11: 2025 PROJECTION | D11: 2025 BUDGET | E11: % VARIANCE | G11: Q1 | H11: Q2 | I11: Q3 | J11: Q4 | K11: FY | M11: Growth %
B12: Sales Volume( KG) | C12: =SUM(C14:C17) -> 17576.76 | D12: 39420 | E12: =C12/D12-1 -> -0.55411568 | G12: =SUM(G14:G17) -> 10617.016 | H12: =SUM(H14:H17) -> 9339.1224 | I12: =SUM(I14:I17) -> 10348.248 | J12: =SUM(J14:J17) -> 12195.616 | K12: =([1]ASSUMPTIONS!M15)*N43 -> 42500 | M12: =K12/C12-1 -> 1.4179655
B14: Bitumen Emulsions | C14: 3906.14 | D14: 14851 | E14: =C14/D14-1 -> -0.73697798 | G14: =K14*O14 -> 1937.1195 | H14: =K14*P14 -> 1851.3009 | I14: =K14*Q14 -> 1910.0361 | J14: =K14*R14 -> 1951.5439 | K14: =+[1]ASSUMPTIONS!M13*N43 -> 7650 | M14: =K14/C14-1 -> 0.95845515 | O14: 0.25321824 | P14: 0.24200011 | Q14: 0.24967792 | R14: 0.25510377
B15: PMB | C15: 838.36 | D15: 7069 | E15: =C15/D15-1 -> -0.88140331 | G15: =K15*O15 -> 1837.5644 | H15: =K15*P15 -> 2195.4561 | I15: =K15*Q15 -> 2291.1573 | J15: =K15*R15 -> 2175.8247 | K15: =+[1]ASSUMPTIONS!M14*N43 -> 8500 | M15: =K15/C15-1 -> 9.1388425 | O15: 0.21618405 | P15: 0.25828895 | Q15: 0.26954792 | R15: 0.25597938
B16: AC 10 | C16: 2971.34 | D16: 8750 | E16: =C16/D16-1 -> -0.66041829 | G16: =K16*O16 -> 1143.69 | H16: =K16*P16 -> 712.31296 | I16: =K16*Q16 -> 1201.6892 | J16: =K16*R16 -> 1192.3046 | K16: =[1]ASSUMPTIONS!M11*N43 -> 4250 | M16: =K16/C16-1 -> 0.4303311 | O16: 0.26910353 | P16: 0.16760305 | Q16: 0.2827504 | R16: 0.28054227
B17: AC 20 | C17: 9860.92 | D17: 8750 | E17: =C17/D17-1 -> 0.12696229 | G17: =K17*O17 -> 5698.6419 | H17: =K17*P17 -> 4580.0524 | I17: =K17*Q17 -> 4945.3649 | J17: =K17*R17 -> 6875.9432 | K17: =[1]ASSUMPTIONS!M12*N43 -> 22100 | M17: =K17/C17-1 -> 1.2411702 | O17: 0.2578571 | P17: 0.20724219 | Q17: 0.22377217 | R17: 0.31112865
B19: Sales Mix
B20: Bitumen Emulsions | C20: =C14/C$12 -> 0.22223322 | D20: =D14/$D$12 -> 0.3767377 | G20: =G14/$G$12 -> 0.18245424 | H20: =H14/$H$12 -> 0.19823071 | I20: =I14/$I$12 -> 0.18457581 | J20: =J14/$J$12 -> 0.16002011 | K20: =K14/$K$12 -> 0.18
B21: PMB | C21: =C15/C$12 -> 0.047697073 | D21: =D15/$D$12 -> 0.17932522 | G21: =G15/$G$12 -> 0.1730773 | H21: =H15/$H$12 -> 0.23508163 | I21: =I15/$I$12 -> 0.22140535 | J21: =J15/$J$12 -> 0.17841039 | K21: =K15/$K$12 -> 0.2
B22: AC 10 | C22: =C16/C$12 -> 0.16904936 | D22: =D16/$D$12 -> 0.22196854 | G22: =G16/$G$12 -> 0.10772236 | H22: =H16/$H$12 -> 0.076271938 | I22: =I16/$I$12 -> 0.1161249 | J22: =J16/$J$12 -> 0.097765017 | K22: =K16/$K$12 -> 0.1
B23: AC 20 | C23: =C17/C$12 -> 0.56102035 | D23: =D17/$D$12 -> 0.22196854 | G23: =G17/$G$12 -> 0.5367461 | H23: =H17/$H$12 -> 0.49041572 | I23: =I17/$I$12 -> 0.47789395 | J23: =J17/$J$12 -> 0.56380448 | K23: =K17/$K$12 -> 0.52
B25: Price per Unit(GHC)
B26: Bitumen Emulsions | C26: 10.02 | D26: =D32/D14 -> 9.8120624 | G26: 11 | H26: 11 | I26: 11 | J26: 11 | K26: =AVERAGE(G26:J26) -> 11
B27: PMB | C27: 16.03 | D27: =D33/D15 -> 13.018171 | G27: 15.2 | H27: 15.2 | I27: 15.2 | J27: 15.2 | K27: =AVERAGE(G27:J27) -> 15.2
B28: AC 10 | C28: 12.26 | D28: =D34/D16 -> 12.007061 | G28: 12.8 | H28: 12.8 | I28: 12.8 | J28: 12.8 | K28: =AVERAGE(G28:J28) -> 12.8
B29: AC 20 | C29: 12.6 | D29: =D35/D17 -> 11.975589 | G29: 12.8 | H29: 12.8 | I29: 12.8 | J29: 12.8 | K29: =AVERAGE(G29:J29) -> 12.8
B31: GHC'000
B32: Bitumen Emulsions | C32: =C14*C26 -> 39139.523 | D32: 145718.94 | E32: =C32/D32-1 -> -0.73140401 | G32: =G14*G26 -> 21308.315 | H32: =H14*H26 -> 20364.309 | I32: =I14*I26 -> 21010.397 | J32: =J14*J26 -> 21466.983 | K32: =K14*K26 -> 84150 | M32: =K32/C32-1 -> 1.1500007
B33: PMB | C33: =C15*C27 -> 13438.911 | D33: 92025.452 | E33: =C33/D33-1 -> -0.85396528 | G33: =G15*G27 -> 27930.979 | H33: =H15*H27 -> 33370.933 | I33: =I15*I27 -> 34825.591 | J33: =J15*J27 -> 33072.536 | K33: =K15*K27 -> 129200 | M33: =K33/C33-1 -> 8.6138744
B34: AC 10 | C34: =C16*C28 -> 36428.628 | D34: 105061.78 | E34: =C34/D34-1 -> -0.6532647 | G34: =G16*G28 -> 14639.232 | H34: =H16*H28 -> 9117.6059 | I34: =I16*I28 -> 15381.622 | J34: =J16*J28 -> 15261.5 | K34: =K16*K28 -> 54400 | M34: =K34/C34-1 -> 0.493331
B35: AC 20 | C35: =C17*C29 -> 124247.59 | D35: 104786.4 | E35: =C35/D35-1 -> 0.1857225 | G35: =G17*G29 -> 72942.616 | H35: =H17*H29 -> 58624.671 | I35: =I17*I29 -> 63300.67 | J35: =J17*J29 -> 88012.073 | K35: =K17*K29 -> 282880 | M35: =K35/C35-1 -> 1.2767443
B37: Total Revenue | C37: =SUM(C32:C35) -> 213254.65 | D37: =SUM(D32:D35) -> 447592.57 | E37: =C37/D37-1 -> -0.52355185 | G37: =SUM(G32:G35) -> 136821.14 | H37: =SUM(H32:H35) -> 121477.52 | I37: =SUM(I32:I35) -> 134518.28 | J37: =SUM(J32:J35) -> 157813.09 | K37: =SUM(K32:K35) -> 550630 | M37: =K37/C37-1 -> 1.5820304 | O37: >> Average Revenue Growth
G41: Scenarios:
G42: Revenue % growth
G43: Selected Case | N43: =VLOOKUP($H$7,$G44:$N46,COLUMNS($G44:N46),FALSE) -> 0.64393939
G44: Best case | N44: 1
G45: Base case | N45: 0.85606061
G46: Worst case | N46: 0.64393939

Sheet COGS -Direct Materials
B2: GOBITUMEN LIMITED
B3: DIRECT MATERIAL PURCHASES BUDGET FY 2026
C5: FY 2025 ANALYSIS | G5: 2026 RAW MATERIALS PURCHASES BUDGET
B6: in '000 | C6: 2025 PROJECTED | D6: 2025 BUDGET | E6: % VARIANCE | G6: Q1 | H6: Q2 | I6: Q3 | J6: Q4 | K6: FY | M6: Growth %
B7: Production/Sales Volume'000
B8: Bitumen Emulsions (Mt) | C8: ='SALES BUDGET'!C14 -> 3906.14 | D8: 14851 | E8: =C8/D8-1 -> -0.73697798 | G8: =+'SALES BUDGET'!G14 -> 1937.1195 | H8: =+'SALES BUDGET'!H14 -> 1851.3009 | I8: =+'SALES BUDGET'!I14 -> 1910.0361 | J8: =+'SALES BUDGET'!J14 -> 1951.5439 | K8: =+'SALES BUDGET'!K14 -> 7650 | M8: =K8/C8-1 -> 0.95845515
B9: PMB (Mt) | C9: ='SALES BUDGET'!C15 -> 838.36 | D9: 7069 | E9: =C9/D9-1 -> -0.88140331 | G9: =+'SALES BUDGET'!G15 -> 1837.5644 | H9: =+'SALES BUDGET'!H15 -> 2195.4561 | I9: =+'SALES BUDGET'!I15 -> 2291.1573 | J9: =+'SALES BUDGET'!J15 -> 2175.8247 | K9: =+'SALES BUDGET'!K15 -> 8500 | M9: =K9/C9-1 -> 9.1388425
B10: AC 10 direct Sales (kg) | C10: ='SALES BUDGET'!C16 -> 2971.34 | D10: 8750 | E10: =C10/D10-1 -> -0.66041829 | G10: =+'SALES BUDGET'!G16 -> 1143.69 | H10: =+'SALES BUDGET'!H16 -> 712.31296 | I10: =+'SALES BUDGET'!I16 -> 1201.6892 | J10: =+'SALES BUDGET'!J16 -> 1192.3046 | K10: =+'SALES BUDGET'!K16 -> 4250 | M10: =K10/C10-1 -> 0.4303311
B11: AC 20 direct Sales (kg) | C11: ='SALES BUDGET'!C17 -> 9860.92 | D11: 8750 | E11: =C11/D11-1 -> 0.12696229 | G11: =+'SALES BUDGET'!G17 -> 5698.6419 | H11: =+'SALES BUDGET'!H17 -> 4580.0524 | I11: =+'SALES BUDGET'!I17 -> 4945.3649 | J11: =+'SALES BUDGET'!J17 -> 6875.9432 | K11: =+'SALES BUDGET'!K17 -> 22100 | M11: =K11/C11-1 -> 1.2411702
B13: Direct Material Used in prodn/sales:'000
B14: Amino (kg) | C14: 14.04 | D14: 53.427793 | E14: =C14/D14-1 -> -0.73721543 | G14: =G8*[1]ASSUMPTIONS!$N$56 -> 6.9600612 | H14: =H8*[1]ASSUMPTIONS!$N$56 -> 6.651715 | I14: =I8*[1]ASSUMPTIONS!$N$56 -> 6.8627506 | J14: =J8*[1]ASSUMPTIONS!$N$56 -> 7.0118877 | K14: =SUM(G14:J14) -> 27.486414 | M14: =K14/C14-1 -> 0.95772183
B15: HCL (kg) | C15: 10.01 | D15: 38.040267 | E15: =C15/D15-1 -> -0.73685779 | G15: =G8*[1]ASSUMPTIONS!$N$57 -> 3.5825794 | H15: =H8*[1]ASSUMPTIONS!$N$57 -> 3.4238632 | I15: =I8*[1]ASSUMPTIONS!$N$57 -> 3.5324903 | J15: =J8*[1]ASSUMPTIONS!$N$57 -> 3.6092563 | K15: =SUM(G15:J15) -> 14.148189 | M15: =K15/C15-1 -> 0.41340551
B16: Production water (m3) | C16: 1834.46 | D16: 6978.445 | E16: =C16/D16-1 -> -0.73712482 | G16: =G8*[1]ASSUMPTIONS!$N$55 -> 764.30518 | H16: =H8*[1]ASSUMPTIONS!$N$55 -> 730.44476 | I16: =I8*[1]ASSUMPTIONS!$N$55 -> 753.61921 | J16: =J8*[1]ASSUMPTIONS!$N$55 -> 769.9964 | K16: =SUM(G16:J16) -> 3018.3656 | M16: =K16/C16-1 -> 0.64537006
B17: Polymer (SBS) | C17: 56.58 | D17: 477.31816 | E17: =C17/D17-1 -> -0.88146271 | G17: =G9*[1]ASSUMPTIONS!$N$65 -> 43.926028 | H17: =H9*[1]ASSUMPTIONS!$N$65 -> 52.481244 | I17: =I9*[1]ASSUMPTIONS!$N$65 -> 54.768932 | J17: =J9*[1]ASSUMPTIONS!$N$65 -> 52.011966 | K17: =SUM(G17:J17) -> 203.18817 | M17: =K17/C17-1 -> 2.591166
B18: Cross Link (kg) | C18: 5.17 | D18: 43.6059 | E18: =C18/D18-1 -> -0.88143806 | G18: =G9*[1]ASSUMPTIONS!$N$64 -> 4.0265526 | H18: =H9*[1]ASSUMPTIONS!$N$64 -> 4.8107807 | I18: =I9*[1]ASSUMPTIONS!$N$64 -> 5.0204855 | J18: =J9*[1]ASSUMPTIONS!$N$64 -> 4.7677636 | K18: =SUM(G18:J18) -> 18.625582 | M18: =K18/C18-1 -> 2.6026272
B19: AC 10 (KG) Prodn+Direct Sales | C19: =2485.72545454545+C10 -> 5457.0655 | D19: 19144.316 | E19: =C19/D19-1 -> -0.71495113 | G19: =G10+(G8*[1]ASSUMPTIONS!$N$58) -> 2499.6737 | H19: =H10+(H8*[1]ASSUMPTIONS!$N$58) -> 2008.2236 | I19: =I10+(I8*[1]ASSUMPTIONS!$N$58) -> 2538.7145 | J19: =J10+(J8*[1]ASSUMPTIONS!$N$58) -> 2558.3854 | K19: =SUM(G19:J19) -> 9604.9971 | M19: =K19/C19-1 -> 0.76010296
B20: AC 20 (KG) Prodn+Direct Sales | C20: =816.482369632999+C11 -> 10677.402 | D20: 15858.75 | E20: =C20/D20-1 -> -0.32671854 | G20: =G11+(G9*[1]ASSUMPTIONS!$N$66) -> 7488.2524 | H20: =H11+(H9*[1]ASSUMPTIONS!$N$66) -> 6718.2149 | I20: =I11+(I9*[1]ASSUMPTIONS!$N$66) -> 7176.7311 | J20: =J11+(J9*[1]ASSUMPTIONS!$N$66) -> 8994.9866 | K20: =SUM(G20:J20) -> 30378.185 | M20: =K20/C20-1 -> 1.8450913
C21: =SUM(C14:C20) -> 18054.728 | D21: =SUM(D14:D20) -> 42593.903 | E21: =C21/D21-1 -> -0.57611943 | G21: =SUM(G14:G20) -> 10810.726 | H21: =SUM(H14:H20) -> 9524.2508 | I21: =SUM(I14:I20) -> 10539.249 | J21: =SUM(J14:J20) -> 12390.769 | K21: =SUM(K14:K20) -> 43264.996 | M21: =K21/C21-1 -> 1.396325
B25: Unit Cost of Direct material:
B26: Amino (kg) | C26: -138.43 | D26: -123.8666 | G26: -78.148923 | H26: -78.148923 | I26: -78.148923 | J26: -78.148923 | K26: =AVERAGE(G26:J26) -> -78.148923
B27: HCL (kg) | C27: -21.3 | D27: -13.2275 | G27: -16.10035 | H27: -16.10035 | I27: -16.10035 | J27: -16.10035 | K27: =AVERAGE(G27:J27) -> -16.10035
B28: Production water (m3) | C28: -0.3249 | D28: -0.0368654 | G28: -0.035 | H28: -0.035 | I28: -0.035 | J28: -0.035 | K28: =AVERAGE(G28:J28) -> -0.035
B29: Polymer (SBS) | C29: -72.57 | D29: -50.74 | G29: -26.88432 | H29: -26.88432 | I29: -26.88432 | J29: -26.88432 | K29: =AVERAGE(G29:J29) -> -26.88432
B30: Cross Link (kg) | C30: -166.98 | D30: -122.5 | G30: -76.193712 | H30: -76.193712 | I30: -76.193712 | J30: -76.193712 | K30: =AVERAGE(G30:J30) -> -76.193712
B31: AC 10 (MT) | C31: 10.34 | D31: -10.793097 | G31: -6.7507103 | H31: -6.7507103 | I31: -6.7507103 | J31: -6.7507103 | K31: =AVERAGE(G31:J31) -> -6.7507103
B32: AC 20 (MT) | C32: -10.4 | D32: -10.780965 | G32: -6.8102699 | H32: -6.8102699 | I32: -6.8102699 | J32: -6.8102699 | K32: =AVERAGE(G32:J32) -> -6.8102699
B34: Total Cost of Raw Mat. used in production and Direct Sales
B35: (GHC'000)
B36: Amino | C36: =C14*C26 -> -1943.5572 | D36: -5583.2579 | E36: =D36/C36-1 -> 1.8727006 | G36: =G26*G14 -> -543.92128 | H36: =H14*H26 -> -519.82436 | I36: =I14*I26 -> -536.31656 | J36: =J14*J26 -> -547.97147 | K36: =SUM(G36:J36) -> -2148.0337 | M36: =K36/C36-1 -> 0.10520734
B37: HCL | C37: =C15*C27 -> -213.213 | D37: -324.01801 | E37: =D37/C37-1 -> 0.51969163 | G37: =G27*G15 -> -57.680782 | H37: =H15*H27 -> -55.125396 | I37: =I15*I27 -> -56.87433 | J37: =J15*J27 -> -58.110289 | K37: =SUM(G37:J37) -> -227.7908 | M37: =K37/C37-1 -> 0.06837199
B38: Production water | C38: =C16*C28 -> -596.01605 | D38: -181.01994 | E38: =D38/C38-1 -> -0.69628345 | G38: =G28*G16 -> -26.750681 | H38: =H16*H28 -> -25.565567 | I38: =I16*I28 -> -26.376672 | J38: =J16*J28 -> -26.949874 | K38: =SUM(G38:J38) -> -105.64279 | M38: =K38/C38-1 -> -0.82275176
B39: Polymer | C39: =C17*C29 -> -4106.0106 | D39: -4225.5592 | E39: =D39/C39-1 -> 0.029115515 | G39: =G29*G17 -> -1180.9214 | H39: =H17*H29 -> -1410.9226 | I39: =I17*I29 -> -1472.4255 | J39: =J17*J29 -> -1398.3063 | K39: =SUM(G39:J39) -> -5462.5758 | M39: =K39/C39-1 -> 0.33038522
B40: Cross Link | C40: =C18*C30 -> -863.2866 | D40: -849.06242 | E40: =D40/C40-1 -> -0.016476779 | G40: =G30*G18 -> -306.79799 | H40: =H18*H30 -> -366.55124 | I40: =I18*I30 -> -382.52943 | J40: =J18*J30 -> -363.27361 | K40: =SUM(G40:J40) -> -1419.1523 | M40: =K40/C40-1 -> 0.6438947
B41: AC 10 | C41: =-42800.5*1.1 -> -47080.55 | D41: -209398.09 | E41: =D41/C41-1 -> 3.447656 | G41: =G31*G19 -> -16874.573 | H41: =H19*H31 -> -13556.935 | I41: =I19*I31 -> -17138.126 | J41: =J19*J31 -> -17270.918 | K41: =SUM(G41:J41) -> -64840.553 | M41: =K41/C41-1 -> 0.3772259
B42: AC 20 | C42: =-104088.75*1.1 -> -114497.63 | D42: -168516.77 | E42: =D42/C42-1 -> 0.47179267 | G42: =G32*G20 -> -50997.02 | H42: =H20*H32 -> -45752.857 | I42: =I20*I32 -> -48875.476 | J42: =J20*J32 -> -61258.286 | K42: =SUM(G42:J42) -> -206883.64 | M42: =K42/C42-1 -> 0.80688149
B44: Total Cost (Direct Materials) | C44: =SUM(C36:C42) -> -169300.26 | D44: =SUM(D36:D42) -> -389077.78 | E44: =D44/C44-1 -> 1.2981523 | G44: =SUM(G36:G42) -> -69987.665 | H44: =SUM(H36:H42) -> -61687.781 | I44: =SUM(I36:I42) -> -68488.124 | J44: =SUM(J36:J42) -> -80923.816 | K44: =SUM(K36:K42) -> -281087.39 | M44: =K44/C44-1 -> 0.66028918

Sheet COGS - Factory Overheads
B1: GOBITUMEN LIMITED
B2: PRODUCTION OVERHEADS
C4: FY 2025 ANALYSIS | G4: 2026 BUDGETED FACTORY OVERHEADS
B5: in GHC'000 | C5: 2025 PROJECTIONS | D5: 2025 BUDGET | E5: % VARIANCE | G5: Q1 | H5: Q2 | I5: Q3 | J5: Q4 | K5: FY | L5: Growth %
B6: Production Volume:
B7: Emulsions | C7: ='COGS -Direct Materials'!C8 -> 3906.14 | D7: 14850.994 | E7: =C7/D7-1 -> -0.73697787 | G7: ='COGS -Direct Materials'!G8 -> 1937.1195 | H7: ='COGS -Direct Materials'!H8 -> 1851.3009 | I7: ='COGS -Direct Materials'!I8 -> 1910.0361 | J7: ='COGS -Direct Materials'!J8 -> 1951.5439 | K7: =SUM(G7:J7) -> 7650.0004 | L7: =K7/C7-1 -> 0.95845525
B8: Polymer modified Bitumen | C8: =+'COGS -Direct Materials'!C9 -> 838.36 | D8: 7069 | E8: =C8/D8-1 -> -0.88140331 | G8: =+'COGS -Direct Materials'!G9 -> 1837.5644 | H8: =+'COGS -Direct Materials'!H9 -> 2195.4561 | I8: =+'COGS -Direct Materials'!I9 -> 2291.1573 | J8: =+'COGS -Direct Materials'!J9 -> 2175.8247 | K8: =SUM(G8:J8) -> 8500.0026 | L8: =K8/C8-1 -> 9.1388456
B11: Direct and Indirect Labor Expense: | C11: -1322.0462 | D11: -1900.958 | E11: =C11/D11-1 -> -0.30453688 | G11: =K11/4 -> -669.63906 | H11: =+G11 -> -669.63906 | I11: =+H11 -> -669.63906 | J11: =+I11 -> -669.63906 | K11: ='[1]Payroll Expense'!N15+'[1]Payroll Expense'!N16 -> -2678.5563 | L11: =K11/C11-1 -> 1.0260686
B13: 2. Other Factory Epenses
B14: HSSE Factory | C14: =-61.77591 -> -61.77591 | D14: =-294.2654967-99.746109316-5.90898958035471 -> -399.9206 | E14: =C14/D14-1 -> -0.84552956 | G14: =$K14/4 -> -124.20876 | H14: =$K14/4 -> -124.20876 | I14: =$K14/4 -> -124.20876 | J14: =$K14/4 -> -124.20876 | K14: =(-'[1]Recurrent cost apportionment'!F122-'[1]Recurrent cost apportionment'!F98-'[1]Recurrent cost apportionment'!F117)/1000 -> -496.83506 | L14: =K14/C14-1 -> 7.0425373
B15: Electricity for Gobitumen | C15: -96.36947 | D15: -763.79166 | E15: =C15/D15-1 -> -0.87382754 | G15: =$K15/4 -> 0 | H15: =$K15/4 -> 0 | I15: =$K15/4 -> 0 | J15: =$K15/4 -> 0 | K15: =-'[1]Recurrent cost apportionment'!F93/1000*'SALES BUDGET'!N43 -> 0 | L15: =K15/C15-1 -> -1
B16: Fuel consumption | C16: -252.27839 | D16: -55.618181 | E16: =C16/D16-1 -> 3.5358979 | G16: =$K16/4 -> 0 | H16: =$K16/4 -> 0 | I16: =$K16/4 -> 0 | J16: =$K16/4 -> 0 | K16: =-'[1]Recurrent cost apportionment'!F95/1000 -> 0 | L16: =K16/C16-1 -> -1
B17: Lab expenses | C17: -54.79792 | D17: -33.789 | E17: =C17/D17-1 -> 0.62176803 | G17: =$K17/4 -> -34.390742 | H17: =$K17/4 -> -34.390742 | I17: =$K17/4 -> -34.390742 | J17: =$K17/4 -> -34.390742 | K17: ='[1]LAB BUDGET-2026'!G80/1000*-1 -> -137.56297 | L17: =K17/C17-1 -> 1.5103684
B18: Maintenance of Plants ,Machinery &Equipments | C18: -257.4 | D18: -1085.5704 | E18: =C18/D18-1 -> -0.76288963 | G18: =$K18/4 -> -321.13432 | H18: =$K18/4 -> -321.13432 | I18: =$K18/4 -> -321.13432 | J18: =$K18/4 -> -321.13432 | K18: =(584978.84+'[1]LAB BUDGET-2026'!G81+'[1]PRODUCTION AND PLANT BUDGET'!T23)/1000*-1 -> -1284.5373 | L18: =K18/C18-1 -> 3.9904323
B19: Security Services | C19: -81.79147 | D19: -62.424243 | E19: =C19/D19-1 -> 0.31025168 | G19: =$K19/4 -> -101.74787 | H19: =$K19/4 -> -101.74787 | I19: =$K19/4 -> -101.74787 | J19: =$K19/4 -> -101.74787 | K19: =('[1]Recurrent cost apportionment'!F111+'[1]Recurrent cost apportionment'!F110)/1000*-1 -> -406.99149 | L19: =K19/C19-1 -> 3.975965
B20: Cleaning Services | C20: -89.76221 | D20: -24.91883 | E20: =C20/D20-1 -> 2.602184 | G20: =$K20/4 -> -16.38351 | H20: =$K20/4 -> -16.38351 | I20: =$K20/4 -> -16.38351 | J20: =$K20/4 -> -16.38351 | K20: =('[1]Recurrent cost apportionment'!F117+'[1]Recurrent cost apportionment'!F118+'[1]Recurrent cost apportionment'!F119+'[1]Recurrent cost apportionment'!F120+'[1]Recurrent cost apportionment'!F121)/-1000 -> -65.53404 | L20: =K20/C20-1 -> -0.26991504
B21: Permit & Licenses | C21: =-106500/1000 -> -106.5 | D21: -2.9195084 | E21: =C21/D21-1 -> 35.478744 | G21: =$K21/4 -> -34.537963 | H21: =$K21/4 -> -34.537963 | I21: =$K21/4 -> -34.537963 | J21: =$K21/4 -> -34.537963 | K21: ='[1]Recurrent cost apportionment'!F201/-1000 -> -138.15185 | L21: =K21/C21-1 -> 0.29720048
B22: Insurance expense | C22: =-427345.42/1000 -> -427.34542 | D22: -879.49051 | E22: =C22/D22-1 -> -0.51409889 | G22: =$K22/4 -> -307.0908 | H22: =$K22/4 -> -307.0908 | I22: =$K22/4 -> -307.0908 | J22: =$K22/4 -> -307.0908 | K22: ='[1]WORKINGS FOR OTHER ADMIN BUDGET'!C34/1000*-1 -> -1228.3632 | L22: =K22/C22-1 -> 1.8744036
B23: Depreciation:Plant,Machinery and Equipment | C23: -6296.7847 | D23: -7089.2985 | E23: =C23/D23-1 -> -0.11179016 | G23: =$K23/4 -> -1944.1817 | H23: =$K$23/4 -> -1944.1817 | I23: =$K$23/4 -> -1944.1817 | J23: =$K$23/4 -> -1944.1817 | K23: =-('[1]DEPRECIATION WORKINGS'!C14+'[1]DEPRECIATION WORKINGS'!D14)/1000 -> -7776.7269 | L23: =K23/C23-1 -> 0.23503142
B24: Production Overheads | C24: =SUM(C11:C23) -> -9046.8516 | D24: =SUM(D11:D23) -> -12298.699 | E24: =C24/D24-1 -> -0.26440582 | G24: =SUM(G11:G23) -> -3553.3148 | H24: =SUM(H11:H23) -> -3553.3148 | I24: =SUM(I11:I23) -> -3553.3148 | J24: =SUM(J11:J23) -> -3553.3148 | K24: =SUM(K11:K23) -> -14213.259 | L24: =K24/C24-1 -> 0.57107242

Sheet SG&A Expense
C2: GOBITUMEN LIMITED
C3: SELLING, GENERAL & ADMINISTRATIVE BUDGET
C6: FY 2025 ANALYSIS | H6: 2026 BUDGETED SELLING,GENERAL AND ADMINISTRATIVE EXPENSES
B7: in GHC'000 | C7: 2025 PROJECTION | D7: 2025 BUDGET | E7: VARIANCE | H7: Q1 | I7: Q2 | J7: Q3 | K7: Q4 | L7: FY | N7: Growth%
B9: Salaries (Administrative) | C9: =2627868.78/-1000 -> -2627.8688 | D9: -3224.55 | E9: =C9/D9-1 -> -0.18504325 | H9: =$L9/4 -> -1925.4533 | I9: =$L9/4 -> -1925.4533 | J9: =$L9/4 -> -1925.4533 | K9: =$L9/4 -> -1925.4533 | L9: ='[1]SALARIES BUDGET'!L46/-1000 -> -7701.8133 | N9: =L9/C9-1 -> 1.9308211
B10: Staff Cost - Training | C10: =-51277.09/1000 -> -51.27709 | D10: -4404.1179 | E10: =C10/D10-1 -> -0.98835701 | H10: =L10/4 -> -294.22678 | I10: =$L10/4 -> -294.22678 | J10: =$L10/4 -> -294.22678 | K10: =$L10/4 -> -294.22678 | L10: =(('[1]Recurrent cost apportionment'!F92+'[1]Recurrent cost apportionment'!F96+'[1]Recurrent cost apportionment'!F99+'[1]Recurrent cost apportionment'!F100+'[1]Recurrent cost apportionment'!F101+'[1]2026 Mktg Budget - Breakdown '!G30+'[1]LAB BUDGET-2026'!G82+'[1]WORKINGS FOR OTHER ADMIN BUDGET'!C3+'[1]WORKINGS FOR OTHER ADMIN BUDGET'!C4)*0.7)/-1000 -> -1176.9071 | N10: =L10/C10-1 -> 21.951909
B11: Subscriptions | C11: -9.605 | D11: -18.564 | E11: =C11/D11-1 -> -0.48260073 | H11: =$L11/4 -> -73.61525 | I11: =$L11/4 -> -73.61525 | J11: =$L11/4 -> -73.61525 | K11: =$L11/4 -> -73.61525 | L11: =('[1]Recurrent cost apportionment'!F173+'[1]ADMINISTRATIVE BUDGET'!J60)/-1000 -> -294.461 | N11: =L11/C11-1 -> 29.657054
B12: Insurance Expense | C12: =-250526.55/1000 -> -250.52655 | D12: -198.56449 | E12: =C12/D12-1 -> 0.26168856 | H12: =$L12/4 -> -152.85399 | I12: =$L12/4 -> -152.85399 | J12: =$L12/4 -> -152.85399 | K12: =$L12/4 -> -152.85399 | L12: ='[1]OTHER ADMIN EXPENSES GOB (2)'!D2/-1000 -> -611.41596 | N12: =L12/C12-1 -> 1.4405236
B13: Maintenance Of Computers & Accessories | C13: -1.45 | D13: -44.117647 | E13: =C13/D13-1 -> -0.96713333 | H13: =$L13/4 -> -100.14706 | I13: =$L13/4 -> -100.14706 | J13: =$L13/4 -> -100.14706 | K13: =$L13/4 -> -100.14706 | L13: =-'[1]Recurrent cost apportionment'!F110/1000 -> -400.58824 | N13: =L13/C13-1 -> 275.26775
B14: Maintenance Of Administrative Building | C14: =-43122.91/1000 -> -43.12291 | D14: -99.565659 | E14: =C14/D14-1 -> -0.56688973 | H14: =$L14/4 -> 0 | I14: =$L14/4 -> 0 | J14: =$L14/4 -> 0 | K14: =$L14/4 -> 0 | L14: =('[1]Recurrent cost apportionment'!F77+'[1]Recurrent cost apportionment'!F76)/-1000 -> 0 | N14: =L14/C14-1 -> -1
B15: Administration Vehicles Maintenance | C15: =-119717.11/1000 -> -119.71711 | D15: -364.48986 | E15: =C15/D15-1 -> -0.67154886 | H15: =$L15/4 -> -128.27255 | I15: =$L15/4 -> -128.27255 | J15: =$L15/4 -> -128.27255 | K15: =$L15/4 -> -128.27255 | L15: =('[1]MAINTENANCE BUDGET'!I23+'[1]2026 Mktg Budget - Breakdown '!G54-'[1]2026 Mktg Budget - Breakdown '!G53)/-1000 -> -513.0902 | N15: =L15/C15-1 -> 3.2858552
B16: Electricity | C16: -57.65 | D16: -35.7 | E16: =C16/D16-1 -> 0.61484594 | H16: =$L16/4 -> -181.982 | I16: =$L16/4 -> -181.982 | J16: =$L16/4 -> -181.982 | K16: =$L16/4 -> -181.982 | L16: =-('[1]Recurrent cost apportionment'!F171-10000)/1000 -> -727.928 | N16: =L16/C16-1 -> 11.626678
B17: Corporate Social Responsibility-Donations | C17: =-200000/1000 -> -200 | D17: -167.61745 | E17: =C17/D17-1 -> 0.19319319 | H17: =L17/4 -> -200 | I17: =L17/4 -> -200 | J17: =L17/4 -> -200 | K17: =L17/4 -> -200 | L17: =('[1]ADMINISTRATIVE BUDGET'!J103)/1000*-1 -> -800 | N17: =L17/C17-1 -> 3
B18: Software License | C18: =-45670/1000 -> -45.67 | D18: -221.99918 | E18: =C18/D18-1 -> -0.79427852 | H18: =$L18/4 -> 0 | I18: =$L18/4 -> 0 | J18: =$L18/4 -> 0 | K18: =$L18/4 -> 0 | L18: ='[1]Recurrent cost apportionment'!F200/-1000 -> 0 | N18: =L18/C18-1 -> -1
B19: Board of Directors Expenses | C19: =-1650484.63/1000 -> -1650.4846 | D19: -1200 | E19: =C19/D19-1 -> 0.37540386 | H19: =$L19/4 -> -573.37202 | I19: =$L19/4 -> -573.37202 | J19: =$L19/4 -> -573.37202 | K19: =$L19/4 -> -573.37202 | L19: =-'[1]OTHER ADMIN EXPENSES GOB (2)'!D10/1000 -> -2293.4881 | N19: =L19/C19-1 -> 0.38958464
B20: Canteen | C20: =-651294.22/1000 -> -651.29422 | D20: -485.59871 | E20: =C20/D20-1 -> 0.341219 | H20: =$L20/4 -> -150 | I20: =$L20/4 -> -150 | J20: =$L20/4 -> -150 | K20: =$L20/4 -> -150 | L20: =('[1]Recurrent cost apportionment'!F170+600000)/1000*-1 -> -600 | N20: =L20/C20-1 -> -0.07875737
B21: Postage & Telephone | C21: =-153142.96/1000 -> -153.14296 | D21: -90.640182 | E21: =C21/D21-1 -> 0.68957031 | H21: =$L21/4 -> 0 | I21: =$L21/4 -> 0 | J21: =$L21/4 -> 0 | K21: =$L21/4 -> 0 | L21: =('[1]Recurrent cost apportionment'!F160)/1000*-1 -> 0 | N21: =L21/C21-1 -> -1
B22: Professional Services | C22: =-4623538.15/1000 -> -4623.5382 | D22: -7456.8996 | E22: =C22/D22-1 -> -0.37996508 | H22: =$L22/4 -> -2316.2817 | I22: =$L22/4 -> -2316.2817 | J22: =$L22/4 -> -2316.2817 | K22: =$L22/4 -> -2316.2817 | L22: =-('[1]OTHER ADMIN EXPENSES GOB (2)'!D12-'[1]ADMINISTRATIVE BUDGET'!J88)/1000 -> -9265.1268 | N22: =L22/C22-1 -> 1.003904
B23: Cleaning Services | C23: -3.17 | D23: -6.39625 | E23: =C23/D23-1 -> -0.50439711 | H23: =$L23/4 -> 0 | I23: =$L23/4 -> 0 | J23: =$L23/4 -> 0 | K23: =$L23/4 -> 0 | L23: =-'[1]Recurrent cost apportionment'!F174/1000 -> 0 | N23: =L23/C23-1 -> -1
B24: Printing & Stationery | C24: -59.53625 | D24: -67.155341 | E24: =C24/D24-1 -> -0.11345473 | H24: =$L24/4 -> 0 | I24: =$L24/4 -> 0 | J24: =$L24/4 -> 0 | K24: =$L24/4 -> 0 | L24: =-'[1]Recurrent cost apportionment'!F160/1000 -> 0 | N24: =L24/C24-1 -> -1
B25: Transport Expenses | C25: =-353570.37/1000 -> -353.57037 | D25: -88.30664 | E25: =C25/D25-1 -> 3.0038934 | H25: =$L25/4 -> -114.426 | I25: =$L25/4 -> -114.426 | J25: =$L25/4 -> -114.426 | K25: =$L25/4 -> -114.426 | L25: =('[1]Recurrent cost apportionment'!F175+'[1]OTHER ADMIN EXPENSES GOB (2)'!D13)/-1000 -> -457.704 | N25: =L25/C25-1 -> 0.29452024
B26: Travels | C26: =-750710.67/1000 -> -750.71067 | D26: - | E26: - | H26: =$L26/4 -> -801.9935 | I26: =$L26/4 -> -801.9935 | J26: =$L26/4 -> -801.9935 | K26: =$L26/4 -> -801.9935 | L26: =('[1]ADMINISTRATIVE BUDGET'!K80*0.7)/-1000 -> -3207.974 | N26: =L26/C26-1 -> 3.2732495
B27: Business Promotion | C27: =-319-15 -> -334 | D27: -91 | E27: =C27/D27-1 -> 2.6703297 | H27: =$L27/4 -> -892.66079 | I27: =$L27/4 -> -892.66079 | J27: =$L27/4 -> -892.66079 | K27: =$L27/4 -> -892.66079 | L27: =('[1]2026 Mktg Budget - Breakdown '!G11+'[1]2026 Mktg Budget - Breakdown '!G10+'[1]ADMINISTRATIVE BUDGET'!J101+'[1]ADMINISTRATIVE BUDGET'!J102+'[1]2026 Mktg Budget - Breakdown '!G12+1456.36+100-1800000)/-1000 -> -3570.6432 | N27: =L27/C27-1 -> 9.6905484
B28: Audit Expenses | C28: -200 | D28: -295.54527 | E28: =C28/D28-1 -> -0.32328472 | H28: =$L28/4 -> -83.567925 | I28: =$L28/4 -> -83.567925 | J28: =$L28/4 -> -83.567925 | K28: =$L28/4 -> -83.567925 | L28: =-+'[1]OTHER ADMIN EXPENSES GOB (2)'!D14/1000 -> -334.2717 | N28: =L28/C28-1 -> 0.6713585
B29: Incorporation Expenses | C29: 0 | E29: =C29/D29-1 -> #DIV/0! | H29: =$L29/4 -> 0 | I29: =$L29/4 -> 0 | J29: =$L29/4 -> 0 | K29: =$L29/4 -> 0 | N29: =L29/C29-1 -> #DIV/0!
B30: Other Hsse Expenses | C30: =-43482.97/1000 -> -43.48297 | D30: -73.267495 | E30: =C30/D30-1 -> -0.40651758 | H30: =$L30/4 -> -154.39604 | I30: =$L30/4 -> -154.39604 | J30: =$L30/4 -> -154.39604 | K30: =$L30/4 -> -154.39604 | L30: =-('[1]Recurrent cost apportionment'!F104+'[1]Recurrent cost apportionment'!F102+'[1]HSSE BUDGET-2026'!K76)/1000 -> -617.58417 | N30: =L30/C30-1 -> 13.202897
B31: Bank Charges | C31: =-216756.27/1000 -> -216.75627 | D31: -4314.7826 | E31: =C31/D31-1 -> -0.94976427 | H31: =$L$31/4 -> -24.665086 | I31: =$L$31/4 -> -24.665086 | J31: =$L$31/4 -> -24.665086 | K31: =$L$31/4 -> -24.665086 | L31: ='[1]WORKINGS FOR OTHER ADMIN BUDGET'!B27/-1000 -> -98.660346 | N31: =L31/C31-1 -> -0.54483279
B32: Foreign Exchage Losses | C32: =-1448622/1000 -> -1448.622 | D32: -9000 | E32: =C32/D32-1 -> -0.839042 | H32: =$L$32/4 -> -109.74243 | I32: =$L$32/4 -> -109.74243 | J32: =$L$32/4 -> -109.74243 | K32: =$L$32/4 -> -109.74243 | L32: =('[1]WORKINGS FOR OTHER ADMIN BUDGET'!B46*0.7)/1000 -> -438.96972 | N32: =L32/C32-1 -> -0.69697428
B33: Depreciation | C33: =-1747984.36/1000 -> -1747.9844 | D33: -2098.1323 | E33: =C33/D33-1 -> -0.16688553 | H33: =L33/4 -> -938.06815 | I33: =L33/4 -> -938.06815 | J33: =L33/4 -> -938.06815 | K33: =L33/4 -> -938.06815 | L33: =('[1]DEPRECIATION WORKINGS'!E14+'[1]DEPRECIATION WORKINGS'!F14+'[1]DEPRECIATION WORKINGS'!G14+'[1]DEPRECIATION WORKINGS'!I14+'[1]DEPRECIATION WORKINGS'!E28)/-1000 -> -3752.2726 | N33: =L33/C33-1 -> 1.1466283
B34: SG&A Expense | C34: =SUM(C9:C33) -> -15643.18 | D34: =SUM(D9:D33) -> -34047.011 | E34: =C34/D34-1 -> -0.54054174 | H34: =SUM(H9:H33) -> -9215.7246 | I34: =SUM(I9:I33) -> -9215.7246 | J34: =SUM(J9:J33) -> -9215.7246 | K34: =SUM(K9:K33) -> -9215.7246 | L34: =SUM(L9:L33) -> -36862.898 | N34: =L34/C34-1 -> 1.3564836

Sheet CAPEX ESTIMATE
B1: GOBITUMEN LIMITED
B2: CAPEX ESTIMATE FOR 2026
A3: A/C CODE | B3: DESCRIPTION | C3: QTY | D3: AMOUNT | E3: BASIS OF APPORTIONMENT | F3: ABT LTD | G3: GOBITUMEN LTD
D4: GHS | F4: GHS | G4: GHS
B5: FIXTURES & FIXTURES
B6: Water Hydrant | C6: 2 | D6: ='[1]2027 HSSE'!G67 -> 432208 | E6: Working Hours | F6: =[1]ASSUMPTIONS!$N$48/[1]ASSUMPTIONS!$O$48*'CAPEX ESTIMATE'!D6 -> 321460.59 | G6: =D6*[1]ASSUMPTIONS!$M$48/[1]ASSUMPTIONS!$O$48 -> 110747.41
B7: Access Control System | C7: 16 | D7: ='[1]2027 HSSE'!G68 -> 325745 | E7: Working Hours | F7: =[1]ASSUMPTIONS!$N$48/[1]ASSUMPTIONS!$O$48*'CAPEX ESTIMATE'!D7 -> 242277.28 | G7: =D7-F7 -> 83467.717
B8: Motion sensors | C8: 4 | D8: ='[1]2027 HSSE'!G69 -> 364675.5 | E8: Working Hours | F8: - | G8: =+D8 -> 364675.5
B9: RAISING OF ALL PANELS, JUNCTION BOXES, TRANSFORMERS CONTROL PANELS | C9: 5 | D9: ='[1]2027 MAINTENANCE'!L77 -> 950000 | E9: Working Hours | F9: =D9*0.6 -> 570000 | G9: =D9-F9 -> 380000
B10: RAISING OF SERVER RACK IN SERVER ROOM | D10: ='[1]2027 MAINTENANCE'!L83 -> 55000 | E10: Working Hours
B11: Fabricating of waste bins & barrel containment trays | D11: ='[1]2027 HSSE'!G71 -> 156452.94 | E11: Working Hours
B12: Irrigation set up | D12: ='[1]2027 HSSE'!G72 -> 337662.5 | E12: Working Hours
B13: water source for the truck park washrooms | D13: ='[1]2027 HSSE'!G73 -> 98745 | E13: Working Hours
B14: Safety signages and labels | D14: ='[1]2027 HSSE'!G6 -> 271269.84 | E14: Working Hours
B15: Safety equipments | D15: ='[1]2027 HSSE'!G7 -> 234781.56 | E15: Working Hours
B16: DINNING TABLE | D16: ='[1]2027 ADMIN'!J118 -> 20676.6
B17: DINNING TABLE CHAIRS | D17: ='[1]2027 ADMIN'!J119 -> 36758.4
B18: LAB CHAIRS | D18: ='[1]2027 ADMIN'!J120 -> 16417.22
B19: EXECUTIVE SWIVEL CHAIR | D19: ='[1]2027 ADMIN'!J121 -> 39725
B20: SWIVEL CHAIRS | D20: ='[1]2027 ADMIN'!J122 -> 50542.8
B23: SUB-TOTAL | D23: =SUM(D6:D22) -> 3390660.4 | F23: =SUM(F6:F22) -> 1133737.9 | G23: =SUM(G6:G22) -> 938890.63
B25: COMPUTER AND ACCESSORIES
B26: LAPTOP FOR PROGRAMMING CONTROLS | C26: 2 | D26: ='[1]2027 ADMIN'!J125 -> 57435 | E26: Allocated To Gobitumen | F26: - | G26: =+D26 -> 57435
B27: DESKTOP COMPUTER | D27: ='[1]2027 ADMIN'!J123 -> 17592.5 | E27: Aloocated To Gobitumen | F27: - | G27: =D27 -> 17592.5
B28: LAPTOP COMPUTER | D28: ='[1]2027 ADMIN'!J124 -> 68922
B31: SUB-TOTAL | D31: =SUM(D26:D30) -> 143949.5 | F31: =SUM(F26:F30) -> 0 | G31: =SUM(G26:G30) -> 75027.5
B33: EQUIPMENTS
B34: LAB
B35: FUME CONTAINMENT/ EXTRACTION SYSTEM | D35: ='[1]2027 LABORATORY'!G48 -> 321205 | E35: Allocated To Gobitumen | G35: =D35 -> 321205
B36: ATMO AGILIS BITUMEN EMULSION PILOT - VIALAB | C36: 2 | D36: ='[1]2027 LABORATORY'!G49 -> 309117.91 | E36: Allocated To Gobitumen | F36: - | G36: =+D36 -> 309117.91
B37: MOISTURE ANALYSER- VIALAB | D37: ='[1]2027 LABORATORY'!G50 -> 56133.283 | E37: Allocated To Gobitumen | F37: - | G37: =D37 -> 56133.283
B38: SETTLING TENDENCY APPARATUS - VIALAB | D38: ='[1]2027 LABORATORY'!G51 -> 6954.255 | E38: Allocated To Gobitumen | G38: =D38 -> 6954.255
B39: BREAKING INDEX APPARATUS - VIALAB | C39: 2 | D39: ='[1]2027 LABORATORY'!G52 -> 30731.4 | E39: Allocated To Gobitumen | F39: - | G39: =D39 -> 30731.4
B40: Safety
B41: Mobile First Aid Container | D41: ='[1]2027 HSSE'!G66 -> 305135.47
B42: Safety equipments | D42: ='[1]2027 HSSE'!G7 -> 234781.56
B43: Movable security post | D43: ='[1]2027 HSSE'!G70 -> 62129.9
B46: SUB-TOTAL | D46: =SUM(D35:D43) -> 1326188.8 | F46: =SUM(F35:F43) -> 0 | G46: =SUM(G35:G43) -> 724141.85
B48: PLANT AND MACHINERY
B49: THERMOMETER INSTALLATION ON PIPELINES + HEAT TRACING CABLE REPAIR | D49: ='[1]2027 MAINTENANCE'!L13 -> 500000 | E49: Allocated To Gobitumen | G49: =D49 -> 500000
...
